PS C:\Users\Administrator\Desktop\babylon-app> & "C:/Program Files/Python312/python.exe" c:/Users/Administrator/Desktop/babylon-app/bbsl_app.py
DEBUG: app_tools/gemini.py imported Config. Has GEMINI_API_KEY: True
Archivos seleccionados: ['C:/Users/Administrator/Desktop/entrada/01.png']
Resultados se guardarán en: C:/Users/Administrator/Desktop/salida

Procesando: C:/Users/Administrator/Desktop/entrada/01.png
2025-08-24 23:55:40,874 - INFO - AFC is enabled with max remote calls: 10.
2025-08-24 23:56:06,635 - INFO - HTTP Request: POST https://generativelanguage.googleapis.com/v1beta/models/gemini-2.5-pro:generateContent "HTTP/1.1 500 Internal Server Error"
2025-08-24 23:56:06,637 - ERROR - Error procesando C:/Users/Administrator/Desktop/entrada/01.png: 500 INTERNAL. {'error': {'code': 500, 'message': 'An internal error has occurred. Please retry or report in https://developers.generativeai.google/guide/troubleshooting', 'status': 'INTERNAL'}}
Traceback (most recent call last):
  File "c:\Users\Administrator\Desktop\babylon-app\app_tools\gemini.py", line 184, in process_file
    response = client.models.generate_content(**api_kwargs)
               ^^^^^^^^^^^^^^^^^^^^^^^^^^^^^^^^^^^^^^^^^^^^
  File "C:\Program Files\Python312\Lib\site-packages\google\genai\models.py", line 6426, in generate_content
    response = self._generate_content(
               ^^^^^^^^^^^^^^^^^^^^^^^
  File "C:\Program Files\Python312\Lib\site-packages\google\genai\models.py", line 5164, in _generate_content
    response = self._api_client.request(
               ^^^^^^^^^^^^^^^^^^^^^^^^^
  File "C:\Program Files\Python312\Lib\site-packages\google\genai\_api_client.py", line 1266, in request
    response = self._request(http_request, http_options, stream=False)
               ^^^^^^^^^^^^^^^^^^^^^^^^^^^^^^^^^^^^^^^^^^^^^^^^^^^^^^^
  File "C:\Program Files\Python312\Lib\site-packages\google\genai\_api_client.py", line 1086, in _request
    return self._retry(self._request_once, http_request, stream)  # type: ignore[no-any-return]
           ^^^^^^^^^^^^^^^^^^^^^^^^^^^^^^^^^^^^^^^^^^^^^^^^^^^^^
  File "C:\Program Files\Python312\Lib\site-packages\tenacity\__init__.py", line 477, in __call__
    do = self.iter(retry_state=retry_state)
         ^^^^^^^^^^^^^^^^^^^^^^^^^^^^^^^^^^
  File "C:\Program Files\Python312\Lib\site-packages\tenacity\__init__.py", line 378, in iter
    result = action(retry_state)
             ^^^^^^^^^^^^^^^^^^^
  File "C:\Program Files\Python312\Lib\site-packages\tenacity\__init__.py", line 420, in exc_check
    raise retry_exc.reraise()
          ^^^^^^^^^^^^^^^^^^^
  File "C:\Program Files\Python312\Lib\site-packages\tenacity\__init__.py", line 187, in reraise
    raise self.last_attempt.result()
          ^^^^^^^^^^^^^^^^^^^^^^^^^^
  File "C:\Program Files\Python312\Lib\concurrent\futures\_base.py", line 449, in result
    return self.__get_result()
           ^^^^^^^^^^^^^^^^^^^
  File "C:\Program Files\Python312\Lib\concurrent\futures\_base.py", line 401, in __get_result
    raise self._exception
  File "C:\Program Files\Python312\Lib\site-packages\tenacity\__init__.py", line 480, in __call__
    result = fn(*args, **kwargs)
             ^^^^^^^^^^^^^^^^^^^
  File "C:\Program Files\Python312\Lib\site-packages\google\genai\_api_client.py", line 1063, in _request_once
    errors.APIError.raise_for_response(response)
  File "C:\Program Files\Python312\Lib\site-packages\google\genai\errors.py", line 107, in raise_for_response
    raise ServerError(status_code, response_json, response)
google.genai.errors.ServerError: 500 INTERNAL. {'error': {'code': 500, 'message': 'An internal error has occurred. Please retry or report in https://developers.generativeai.google/guide/troubleshooting', 'status': 'INTERNAL'}}
2025-08-24 23:56:06,752 - ERROR - Error al procesar C:/Users/Administrator/Desktop/entrada/01.png. Continuando con las demás imágenes.